2023-01-06 22:12:00,471 - INFO -Bot: TEstikanime [@quadroamineskinBot]
2023-01-06 22:12:00,596 - WARNING -Updates were skipped successfully.
2023-01-06 22:12:00,596 - INFO -Start polling.
2023-01-06 22:12:12,971 - ERROR -Task exception was never retrieved
future: <Task finished name='Task-9' coro=<Dispatcher._process_polling_updates() done, defined at D:\Python\Lib\site-packages\aiogram\dispatcher\dispatcher.py:407> exception=OperationalError('no such table: users')>
Traceback (most recent call last):
  File "D:\Python\Lib\site-packages\aiogram\dispatcher\dispatcher.py", line 415, in _process_polling_updates
    for responses in itertools.chain.from_iterable(await self.process_updates(updates, fast)):
                                                   ^^^^^^^^^^^^^^^^^^^^^^^^^^^^^^^^^^^^^^^^^
  File "D:\Python\Lib\site-packages\aiogram\dispatcher\dispatcher.py", line 235, in process_updates
    return await asyncio.gather(*tasks)
           ^^^^^^^^^^^^^^^^^^^^^^^^^^^^
  File "D:\Python\Lib\site-packages\aiogram\dispatcher\handler.py", line 117, in notify
    response = await handler_obj.handler(*args, **partial_data)
               ^^^^^^^^^^^^^^^^^^^^^^^^^^^^^^^^^^^^^^^^^^^^^^^^
  File "D:\Python\Lib\site-packages\aiogram\dispatcher\dispatcher.py", line 256, in process_update
    return await self.message_handlers.notify(update.message)
           ^^^^^^^^^^^^^^^^^^^^^^^^^^^^^^^^^^^^^^^^^^^^^^^^^^
  File "D:\Python\Lib\site-packages\aiogram\dispatcher\handler.py", line 117, in notify
    response = await handler_obj.handler(*args, **partial_data)
               ^^^^^^^^^^^^^^^^^^^^^^^^^^^^^^^^^^^^^^^^^^^^^^^^
  File "D:\ÒÅËÅÃĞÀÌÁÎÒÛ\ANONIMCHAT\main.py", line 60, in start
    count_users = KeyboardButton(f'Â áîòå óæå {int(db.count_user() * 1.5)} ïîëüçîâàòåëåé\U0001f973')
                                                   ^^^^^^^^^^^^^^^
  File "D:\ÒÅËÅÃĞÀÌÁÎÒÛ\ANONIMCHAT\database.py", line 82, in count_user
    result = self.cursor.execute('SELECT COUNT(*) FROM `users`').fetchone()
             ^^^^^^^^^^^^^^^^^^^^^^^^^^^^^^^^^^^^^^^^^^^^^^^^^^^
sqlite3.OperationalError: no such table: users
2023-01-06 22:12:31,276 - ERROR -Task exception was never retrieved
future: <Task finished name='Task-12' coro=<Dispatcher._process_polling_updates() done, defined at D:\Python\Lib\site-packages\aiogram\dispatcher\dispatcher.py:407> exception=OperationalError('no such table: users')>
Traceback (most recent call last):
  File "D:\Python\Lib\site-packages\aiogram\dispatcher\dispatcher.py", line 415, in _process_polling_updates
    for responses in itertools.chain.from_iterable(await self.process_updates(updates, fast)):
                                                   ^^^^^^^^^^^^^^^^^^^^^^^^^^^^^^^^^^^^^^^^^
  File "D:\Python\Lib\site-packages\aiogram\dispatcher\dispatcher.py", line 235, in process_updates
    return await asyncio.gather(*tasks)
           ^^^^^^^^^^^^^^^^^^^^^^^^^^^^
  File "D:\Python\Lib\site-packages\aiogram\dispatcher\handler.py", line 117, in notify
    response = await handler_obj.handler(*args, **partial_data)
               ^^^^^^^^^^^^^^^^^^^^^^^^^^^^^^^^^^^^^^^^^^^^^^^^
  File "D:\Python\Lib\site-packages\aiogram\dispatcher\dispatcher.py", line 256, in process_update
    return await self.message_handlers.notify(update.message)
           ^^^^^^^^^^^^^^^^^^^^^^^^^^^^^^^^^^^^^^^^^^^^^^^^^^
  File "D:\Python\Lib\site-packages\aiogram\dispatcher\handler.py", line 117, in notify
    response = await handler_obj.handler(*args, **partial_data)
               ^^^^^^^^^^^^^^^^^^^^^^^^^^^^^^^^^^^^^^^^^^^^^^^^
  File "D:\ÒÅËÅÃĞÀÌÁÎÒÛ\ANONIMCHAT\main.py", line 60, in start
    count_users = KeyboardButton(f'Â áîòå óæå {int(db.count_user() * 1.5)} ïîëüçîâàòåëåé\U0001f973')
                                                   ^^^^^^^^^^^^^^^
  File "D:\ÒÅËÅÃĞÀÌÁÎÒÛ\ANONIMCHAT\database.py", line 82, in count_user
    result = self.cursor.execute('SELECT COUNT(*) FROM `users`').fetchone()
             ^^^^^^^^^^^^^^^^^^^^^^^^^^^^^^^^^^^^^^^^^^^^^^^^^^^
sqlite3.OperationalError: no such table: users
2023-01-06 22:13:24,889 - ERROR -Task exception was never retrieved
future: <Task finished name='Task-17' coro=<Dispatcher._process_polling_updates() done, defined at D:\Python\Lib\site-packages\aiogram\dispatcher\dispatcher.py:407> exception=OperationalError('no such table: users')>
Traceback (most recent call last):
  File "D:\Python\Lib\site-packages\aiogram\dispatcher\dispatcher.py", line 415, in _process_polling_updates
    for responses in itertools.chain.from_iterable(await self.process_updates(updates, fast)):
                                                   ^^^^^^^^^^^^^^^^^^^^^^^^^^^^^^^^^^^^^^^^^
  File "D:\Python\Lib\site-packages\aiogram\dispatcher\dispatcher.py", line 235, in process_updates
    return await asyncio.gather(*tasks)
           ^^^^^^^^^^^^^^^^^^^^^^^^^^^^
  File "D:\Python\Lib\site-packages\aiogram\dispatcher\handler.py", line 117, in notify
    response = await handler_obj.handler(*args, **partial_data)
               ^^^^^^^^^^^^^^^^^^^^^^^^^^^^^^^^^^^^^^^^^^^^^^^^
  File "D:\Python\Lib\site-packages\aiogram\dispatcher\dispatcher.py", line 256, in process_update
    return await self.message_handlers.notify(update.message)
           ^^^^^^^^^^^^^^^^^^^^^^^^^^^^^^^^^^^^^^^^^^^^^^^^^^
  File "D:\Python\Lib\site-packages\aiogram\dispatcher\handler.py", line 117, in notify
    response = await handler_obj.handler(*args, **partial_data)
               ^^^^^^^^^^^^^^^^^^^^^^^^^^^^^^^^^^^^^^^^^^^^^^^^
  File "D:\ÒÅËÅÃĞÀÌÁÎÒÛ\ANONIMCHAT\main.py", line 60, in start
    count_users = KeyboardButton(f'Â áîòå óæå {int(db.count_user() * 1.5)} ïîëüçîâàòåëåé\U0001f973')
                                                   ^^^^^^^^^^^^^^^
  File "D:\ÒÅËÅÃĞÀÌÁÎÒÛ\ANONIMCHAT\database.py", line 82, in count_user
    result = self.cursor.execute('SELECT COUNT(*) FROM `users`').fetchone()
             ^^^^^^^^^^^^^^^^^^^^^^^^^^^^^^^^^^^^^^^^^^^^^^^^^^^
sqlite3.OperationalError: no such table: users
2023-01-06 22:14:32,331 - INFO -Bot: TEstikanime [@quadroamineskinBot]
2023-01-06 22:14:32,468 - WARNING -Updates were skipped successfully.
2023-01-06 22:14:32,468 - INFO -Start polling.
2023-01-06 22:14:34,845 - ERROR -Task exception was never retrieved
future: <Task finished name='Task-9' coro=<Dispatcher._process_polling_updates() done, defined at D:\Python\Lib\site-packages\aiogram\dispatcher\dispatcher.py:407> exception=OperationalError('no such table: users')>
Traceback (most recent call last):
  File "D:\Python\Lib\site-packages\aiogram\dispatcher\dispatcher.py", line 415, in _process_polling_updates
    for responses in itertools.chain.from_iterable(await self.process_updates(updates, fast)):
                                                   ^^^^^^^^^^^^^^^^^^^^^^^^^^^^^^^^^^^^^^^^^
  File "D:\Python\Lib\site-packages\aiogram\dispatcher\dispatcher.py", line 235, in process_updates
    return await asyncio.gather(*tasks)
           ^^^^^^^^^^^^^^^^^^^^^^^^^^^^
  File "D:\Python\Lib\site-packages\aiogram\dispatcher\handler.py", line 117, in notify
    response = await handler_obj.handler(*args, **partial_data)
               ^^^^^^^^^^^^^^^^^^^^^^^^^^^^^^^^^^^^^^^^^^^^^^^^
  File "D:\Python\Lib\site-packages\aiogram\dispatcher\dispatcher.py", line 256, in process_update
    return await self.message_handlers.notify(update.message)
           ^^^^^^^^^^^^^^^^^^^^^^^^^^^^^^^^^^^^^^^^^^^^^^^^^^
  File "D:\Python\Lib\site-packages\aiogram\dispatcher\handler.py", line 117, in notify
    response = await handler_obj.handler(*args, **partial_data)
               ^^^^^^^^^^^^^^^^^^^^^^^^^^^^^^^^^^^^^^^^^^^^^^^^
  File "D:\ÒÅËÅÃĞÀÌÁÎÒÛ\ANONIMCHAT\main.py", line 60, in start
    count_users = KeyboardButton(f'Â áîòå óæå {int(db.count_user() * 1.5)} ïîëüçîâàòåëåé\U0001f973')
                                                   ^^^^^^^^^^^^^^^
  File "D:\ÒÅËÅÃĞÀÌÁÎÒÛ\ANONIMCHAT\database.py", line 82, in count_user
    result = self.cursor.execute('SELECT COUNT(*) FROM `users`').fetchone()
             ^^^^^^^^^^^^^^^^^^^^^^^^^^^^^^^^^^^^^^^^^^^^^^^^^^^
sqlite3.OperationalError: no such table: users
2023-01-06 22:15:02,424 - ERROR -Task exception was never retrieved
future: <Task finished name='Task-13' coro=<Dispatcher._process_polling_updates() done, defined at D:\Python\Lib\site-packages\aiogram\dispatcher\dispatcher.py:407> exception=OperationalError('no such table: users')>
Traceback (most recent call last):
  File "D:\Python\Lib\site-packages\aiogram\dispatcher\dispatcher.py", line 415, in _process_polling_updates
    for responses in itertools.chain.from_iterable(await self.process_updates(updates, fast)):
                                                   ^^^^^^^^^^^^^^^^^^^^^^^^^^^^^^^^^^^^^^^^^
  File "D:\Python\Lib\site-packages\aiogram\dispatcher\dispatcher.py", line 235, in process_updates
    return await asyncio.gather(*tasks)
           ^^^^^^^^^^^^^^^^^^^^^^^^^^^^
  File "D:\Python\Lib\site-packages\aiogram\dispatcher\handler.py", line 117, in notify
    response = await handler_obj.handler(*args, **partial_data)
               ^^^^^^^^^^^^^^^^^^^^^^^^^^^^^^^^^^^^^^^^^^^^^^^^
  File "D:\Python\Lib\site-packages\aiogram\dispatcher\dispatcher.py", line 256, in process_update
    return await self.message_handlers.notify(update.message)
           ^^^^^^^^^^^^^^^^^^^^^^^^^^^^^^^^^^^^^^^^^^^^^^^^^^
  File "D:\Python\Lib\site-packages\aiogram\dispatcher\handler.py", line 117, in notify
    response = await handler_obj.handler(*args, **partial_data)
               ^^^^^^^^^^^^^^^^^^^^^^^^^^^^^^^^^^^^^^^^^^^^^^^^
  File "D:\ÒÅËÅÃĞÀÌÁÎÒÛ\ANONIMCHAT\main.py", line 60, in start
    count_users = KeyboardButton(f'Â áîòå óæå {int(db.count_user() * 1.5)} ïîëüçîâàòåëåé\U0001f973')
                                                   ^^^^^^^^^^^^^^^
  File "D:\ÒÅËÅÃĞÀÌÁÎÒÛ\ANONIMCHAT\database.py", line 82, in count_user
    result = self.cursor.execute('SELECT COUNT(*) FROM `users`').fetchone()
             ^^^^^^^^^^^^^^^^^^^^^^^^^^^^^^^^^^^^^^^^^^^^^^^^^^^
sqlite3.OperationalError: no such table: users
2023-01-07 18:46:20,558 - WARNING -Goodbye!
2023-01-08 15:01:15,162 - INFO -Bot: ÕåëïåğÁîò [@helperarcher_bot]
2023-01-08 15:01:15,303 - WARNING -Updates were skipped successfully.
2023-01-08 15:01:15,303 - INFO -Start polling.
2023-01-08 15:01:23,858 - ERROR -Task exception was never retrieved
future: <Task finished name='Task-9' coro=<Dispatcher._process_polling_updates() done, defined at D:\Python\Lib\site-packages\aiogram\dispatcher\dispatcher.py:407> exception=OperationalError('no such table: users')>
Traceback (most recent call last):
  File "D:\Python\Lib\site-packages\aiogram\dispatcher\dispatcher.py", line 415, in _process_polling_updates
    for responses in itertools.chain.from_iterable(await self.process_updates(updates, fast)):
                                                   ^^^^^^^^^^^^^^^^^^^^^^^^^^^^^^^^^^^^^^^^^
  File "D:\Python\Lib\site-packages\aiogram\dispatcher\dispatcher.py", line 235, in process_updates
    return await asyncio.gather(*tasks)
           ^^^^^^^^^^^^^^^^^^^^^^^^^^^^
  File "D:\Python\Lib\site-packages\aiogram\dispatcher\handler.py", line 117, in notify
    response = await handler_obj.handler(*args, **partial_data)
               ^^^^^^^^^^^^^^^^^^^^^^^^^^^^^^^^^^^^^^^^^^^^^^^^
  File "D:\Python\Lib\site-packages\aiogram\dispatcher\dispatcher.py", line 256, in process_update
    return await self.message_handlers.notify(update.message)
           ^^^^^^^^^^^^^^^^^^^^^^^^^^^^^^^^^^^^^^^^^^^^^^^^^^
  File "D:\Python\Lib\site-packages\aiogram\dispatcher\handler.py", line 117, in notify
    response = await handler_obj.handler(*args, **partial_data)
               ^^^^^^^^^^^^^^^^^^^^^^^^^^^^^^^^^^^^^^^^^^^^^^^^
  File "D:\ÒÅËÅÃĞÀÌÁÎÒÛ\ANONIMCHAT\main.py", line 60, in start
    count_users = KeyboardButton(f'Â áîòå óæå {int(db.count_user() * 1.5)} ïîëüçîâàòåëåé\U0001f973')
                                                   ^^^^^^^^^^^^^^^
  File "D:\ÒÅËÅÃĞÀÌÁÎÒÛ\ANONIMCHAT\database.py", line 82, in count_user
    result = self.cursor.execute('SELECT COUNT(*) FROM `users`').fetchone()
             ^^^^^^^^^^^^^^^^^^^^^^^^^^^^^^^^^^^^^^^^^^^^^^^^^^^
sqlite3.OperationalError: no such table: users
2023-01-08 15:01:36,552 - ERROR -Task exception was never retrieved
future: <Task finished name='Task-12' coro=<Dispatcher._process_polling_updates() done, defined at D:\Python\Lib\site-packages\aiogram\dispatcher\dispatcher.py:407> exception=OperationalError('no such table: users')>
Traceback (most recent call last):
  File "D:\Python\Lib\site-packages\aiogram\dispatcher\dispatcher.py", line 415, in _process_polling_updates
    for responses in itertools.chain.from_iterable(await self.process_updates(updates, fast)):
                                                   ^^^^^^^^^^^^^^^^^^^^^^^^^^^^^^^^^^^^^^^^^
  File "D:\Python\Lib\site-packages\aiogram\dispatcher\dispatcher.py", line 235, in process_updates
    return await asyncio.gather(*tasks)
           ^^^^^^^^^^^^^^^^^^^^^^^^^^^^
  File "D:\Python\Lib\site-packages\aiogram\dispatcher\handler.py", line 117, in notify
    response = await handler_obj.handler(*args, **partial_data)
               ^^^^^^^^^^^^^^^^^^^^^^^^^^^^^^^^^^^^^^^^^^^^^^^^
  File "D:\Python\Lib\site-packages\aiogram\dispatcher\dispatcher.py", line 256, in process_update
    return await self.message_handlers.notify(update.message)
           ^^^^^^^^^^^^^^^^^^^^^^^^^^^^^^^^^^^^^^^^^^^^^^^^^^
  File "D:\Python\Lib\site-packages\aiogram\dispatcher\handler.py", line 117, in notify
    response = await handler_obj.handler(*args, **partial_data)
               ^^^^^^^^^^^^^^^^^^^^^^^^^^^^^^^^^^^^^^^^^^^^^^^^
  File "D:\ÒÅËÅÃĞÀÌÁÎÒÛ\ANONIMCHAT\main.py", line 60, in start
    count_users = KeyboardButton(f'Â áîòå óæå {int(db.count_user() * 1.5)} ïîëüçîâàòåëåé\U0001f973')
                                                   ^^^^^^^^^^^^^^^
  File "D:\ÒÅËÅÃĞÀÌÁÎÒÛ\ANONIMCHAT\database.py", line 82, in count_user
    result = self.cursor.execute('SELECT COUNT(*) FROM `users`').fetchone()
             ^^^^^^^^^^^^^^^^^^^^^^^^^^^^^^^^^^^^^^^^^^^^^^^^^^^
sqlite3.OperationalError: no such table: users
2023-01-08 15:02:05,811 - INFO -Bot: ÕåëïåğÁîò [@helperarcher_bot]
2023-01-08 15:02:05,936 - WARNING -Updates were skipped successfully.
2023-01-08 15:02:05,951 - INFO -Start polling.
2023-01-08 15:03:00,270 - ERROR -Task exception was never retrieved
future: <Task finished name='Task-11' coro=<Dispatcher._process_polling_updates() done, defined at D:\Python\Lib\site-packages\aiogram\dispatcher\dispatcher.py:407> exception=OperationalError('no such table: users')>
Traceback (most recent call last):
  File "D:\Python\Lib\site-packages\aiogram\dispatcher\dispatcher.py", line 415, in _process_polling_updates
    for responses in itertools.chain.from_iterable(await self.process_updates(updates, fast)):
                                                   ^^^^^^^^^^^^^^^^^^^^^^^^^^^^^^^^^^^^^^^^^
  File "D:\Python\Lib\site-packages\aiogram\dispatcher\dispatcher.py", line 235, in process_updates
    return await asyncio.gather(*tasks)
           ^^^^^^^^^^^^^^^^^^^^^^^^^^^^
  File "D:\Python\Lib\site-packages\aiogram\dispatcher\handler.py", line 117, in notify
    response = await handler_obj.handler(*args, **partial_data)
               ^^^^^^^^^^^^^^^^^^^^^^^^^^^^^^^^^^^^^^^^^^^^^^^^
  File "D:\Python\Lib\site-packages\aiogram\dispatcher\dispatcher.py", line 256, in process_update
    return await self.message_handlers.notify(update.message)
           ^^^^^^^^^^^^^^^^^^^^^^^^^^^^^^^^^^^^^^^^^^^^^^^^^^
  File "D:\Python\Lib\site-packages\aiogram\dispatcher\handler.py", line 117, in notify
    response = await handler_obj.handler(*args, **partial_data)
               ^^^^^^^^^^^^^^^^^^^^^^^^^^^^^^^^^^^^^^^^^^^^^^^^
  File "D:\ÒÅËÅÃĞÀÌÁÎÒÛ\ANONIMCHAT\main.py", line 60, in start
    count_users = KeyboardButton(f'Â áîòå óæå {int(db.count_user() * 1.5)} ïîëüçîâàòåëåé\U0001f973')
                                                   ^^^^^^^^^^^^^^^
  File "D:\ÒÅËÅÃĞÀÌÁÎÒÛ\ANONIMCHAT\database.py", line 82, in count_user
    result = self.cursor.execute('SELECT COUNT(*) FROM `users`').fetchone()
             ^^^^^^^^^^^^^^^^^^^^^^^^^^^^^^^^^^^^^^^^^^^^^^^^^^^
sqlite3.OperationalError: no such table: users
2023-01-08 15:03:03,075 - WARNING -no such table: users
2023-01-08 15:03:03,205 - ERROR -Task exception was never retrieved
future: <Task finished name='Task-14' coro=<Dispatcher._process_polling_updates() done, defined at D:\Python\Lib\site-packages\aiogram\dispatcher\dispatcher.py:407> exception=ChatNotFound('Chat not found')>
Traceback (most recent call last):
  File "D:\ÒÅËÅÃĞÀÌÁÎÒÛ\ANONIMCHAT\main.py", line 250, in chating
    await bot.send_message(db.select_connect_with(message.from_user.id)[0],user_data['msg']) #îòïğàâëÿåì ñîîáùåíèÿ ïîëüçîâàòåëÿ
                           ^^^^^^^^^^^^^^^^^^^^^^^^^^^^^^^^^^^^^^^^^^^^
  File "D:\ÒÅËÅÃĞÀÌÁÎÒÛ\ANONIMCHAT\database.py", line 61, in select_connect_with
    return self.cursor.execute('SELECT `connect_with` FROM `users` WHERE `telegram_id` = ?',(telegram_id,)).fetchone()
           ^^^^^^^^^^^^^^^^^^^^^^^^^^^^^^^^^^^^^^^^^^^^^^^^^^^^^^^^^^^^^^^^^^^^^^^^^^^^^^^^^^^^^^^^^^^^^^^^
sqlite3.OperationalError: no such table: users

During handling of the above exception, another exception occurred:

Traceback (most recent call last):
  File "D:\Python\Lib\site-packages\aiogram\dispatcher\dispatcher.py", line 415, in _process_polling_updates
    for responses in itertools.chain.from_iterable(await self.process_updates(updates, fast)):
                                                   ^^^^^^^^^^^^^^^^^^^^^^^^^^^^^^^^^^^^^^^^^
  File "D:\Python\Lib\site-packages\aiogram\dispatcher\dispatcher.py", line 235, in process_updates
    return await asyncio.gather(*tasks)
           ^^^^^^^^^^^^^^^^^^^^^^^^^^^^
  File "D:\Python\Lib\site-packages\aiogram\dispatcher\handler.py", line 117, in notify
    response = await handler_obj.handler(*args, **partial_data)
               ^^^^^^^^^^^^^^^^^^^^^^^^^^^^^^^^^^^^^^^^^^^^^^^^
  File "D:\Python\Lib\site-packages\aiogram\dispatcher\dispatcher.py", line 256, in process_update
    return await self.message_handlers.notify(update.message)
           ^^^^^^^^^^^^^^^^^^^^^^^^^^^^^^^^^^^^^^^^^^^^^^^^^^
  File "D:\Python\Lib\site-packages\aiogram\dispatcher\handler.py", line 117, in notify
    response = await handler_obj.handler(*args, **partial_data)
               ^^^^^^^^^^^^^^^^^^^^^^^^^^^^^^^^^^^^^^^^^^^^^^^^
  File "D:\ÒÅËÅÃĞÀÌÁÎÒÛ\ANONIMCHAT\main.py", line 264, in chating
    await send_to_channel_log_exception(message,e)
  File "D:\ÒÅËÅÃĞÀÌÁÎÒÛ\ANONIMCHAT\main.py", line 302, in send_to_channel_log_exception
    await bot.send_message(-1001422742707,f'Îøèáêà\n\n{except_name}')
  File "D:\Python\Lib\site-packages\aiogram\bot\bot.py", line 346, in send_message
    result = await self.request(api.Methods.SEND_MESSAGE, payload)
             ^^^^^^^^^^^^^^^^^^^^^^^^^^^^^^^^^^^^^^^^^^^^^^^^^^^^^
  File "D:\Python\Lib\site-packages\aiogram\bot\base.py", line 236, in request
    return await api.make_request(await self.get_session(), self.server, self.__token, method, data, files,
           ^^^^^^^^^^^^^^^^^^^^^^^^^^^^^^^^^^^^^^^^^^^^^^^^^^^^^^^^^^^^^^^^^^^^^^^^^^^^^^^^^^^^^^^^^^^^^^^^
  File "D:\Python\Lib\site-packages\aiogram\bot\api.py", line 140, in make_request
    return check_result(method, response.content_type, response.status, await response.text())
           ^^^^^^^^^^^^^^^^^^^^^^^^^^^^^^^^^^^^^^^^^^^^^^^^^^^^^^^^^^^^^^^^^^^^^^^^^^^^^^^^^^^
  File "D:\Python\Lib\site-packages\aiogram\bot\api.py", line 115, in check_result
    exceptions.BadRequest.detect(description)
  File "D:\Python\Lib\site-packages\aiogram\utils\exceptions.py", line 140, in detect
    raise err(cls.text or description)
aiogram.utils.exceptions.ChatNotFound: Chat not found
2023-01-08 15:10:18,904 - INFO -Bot: ÕåëïåğÁîò [@helperarcher_bot]
2023-01-08 15:10:19,045 - WARNING -Updates were skipped successfully.
2023-01-08 15:10:19,045 - INFO -Start polling.
2023-01-08 15:10:24,128 - ERROR -Task exception was never retrieved
future: <Task finished name='Task-9' coro=<Dispatcher._process_polling_updates() done, defined at D:\Python\Lib\site-packages\aiogram\dispatcher\dispatcher.py:407> exception=OperationalError('no such table: users')>
Traceback (most recent call last):
  File "D:\Python\Lib\site-packages\aiogram\dispatcher\dispatcher.py", line 415, in _process_polling_updates
    for responses in itertools.chain.from_iterable(await self.process_updates(updates, fast)):
                                                   ^^^^^^^^^^^^^^^^^^^^^^^^^^^^^^^^^^^^^^^^^
  File "D:\Python\Lib\site-packages\aiogram\dispatcher\dispatcher.py", line 235, in process_updates
    return await asyncio.gather(*tasks)
           ^^^^^^^^^^^^^^^^^^^^^^^^^^^^
  File "D:\Python\Lib\site-packages\aiogram\dispatcher\handler.py", line 117, in notify
    response = await handler_obj.handler(*args, **partial_data)
               ^^^^^^^^^^^^^^^^^^^^^^^^^^^^^^^^^^^^^^^^^^^^^^^^
  File "D:\Python\Lib\site-packages\aiogram\dispatcher\dispatcher.py", line 256, in process_update
    return await self.message_handlers.notify(update.message)
           ^^^^^^^^^^^^^^^^^^^^^^^^^^^^^^^^^^^^^^^^^^^^^^^^^^
  File "D:\Python\Lib\site-packages\aiogram\dispatcher\handler.py", line 117, in notify
    response = await handler_obj.handler(*args, **partial_data)
               ^^^^^^^^^^^^^^^^^^^^^^^^^^^^^^^^^^^^^^^^^^^^^^^^
  File "D:\ÒÅËÅÃĞÀÌÁÎÒÛ\ANONIMCHAT\main.py", line 60, in start
    count_users = KeyboardButton(f'Â áîòå óæå {int(db.count_user() * 1.5)} ïîëüçîâàòåëåé\U0001f973')
                                                   ^^^^^^^^^^^^^^^
  File "D:\ÒÅËÅÃĞÀÌÁÎÒÛ\ANONIMCHAT\database.py", line 82, in count_user
    result = self.cursor.execute('SELECT COUNT(*) FROM `users`').fetchone()
             ^^^^^^^^^^^^^^^^^^^^^^^^^^^^^^^^^^^^^^^^^^^^^^^^^^^
sqlite3.OperationalError: no such table: users
2023-01-29 02:08:10,118 - WARNING -Goodbye!
2023-01-29 02:08:48,424 - INFO -Bot: Àíîíèìíûé ×àò [@anonimchatarcher_bot]
2023-01-29 02:08:48,549 - WARNING -Updates were skipped successfully.
2023-01-29 02:08:48,549 - INFO -Start polling.
2023-01-29 02:08:53,723 - ERROR -Cause exception while getting updates.
Traceback (most recent call last):
  File "D:\Python\Lib\site-packages\aiogram\dispatcher\dispatcher.py", line 381, in start_polling
    updates = await self.bot.get_updates(
              ^^^^^^^^^^^^^^^^^^^^^^^^^^^
  File "D:\Python\Lib\site-packages\aiogram\bot\bot.py", line 110, in get_updates
    result = await self.request(api.Methods.GET_UPDATES, payload)
             ^^^^^^^^^^^^^^^^^^^^^^^^^^^^^^^^^^^^^^^^^^^^^^^^^^^^
  File "D:\Python\Lib\site-packages\aiogram\bot\base.py", line 236, in request
    return await api.make_request(await self.get_session(), self.server, self.__token, method, data, files,
           ^^^^^^^^^^^^^^^^^^^^^^^^^^^^^^^^^^^^^^^^^^^^^^^^^^^^^^^^^^^^^^^^^^^^^^^^^^^^^^^^^^^^^^^^^^^^^^^^
  File "D:\Python\Lib\site-packages\aiogram\bot\api.py", line 140, in make_request
    return check_result(method, response.content_type, response.status, await response.text())
           ^^^^^^^^^^^^^^^^^^^^^^^^^^^^^^^^^^^^^^^^^^^^^^^^^^^^^^^^^^^^^^^^^^^^^^^^^^^^^^^^^^^
  File "D:\Python\Lib\site-packages\aiogram\bot\api.py", line 119, in check_result
    exceptions.ConflictError.detect(description)
  File "D:\Python\Lib\site-packages\aiogram\utils\exceptions.py", line 140, in detect
    raise err(cls.text or description)
aiogram.utils.exceptions.TerminatedByOtherGetUpdates: Terminated by other getupdates request; make sure that only one bot instance is running
2023-01-29 02:09:04,061 - ERROR -Cause exception while getting updates.
Traceback (most recent call last):
  File "D:\Python\Lib\site-packages\aiogram\dispatcher\dispatcher.py", line 381, in start_polling
    updates = await self.bot.get_updates(
              ^^^^^^^^^^^^^^^^^^^^^^^^^^^
  File "D:\Python\Lib\site-packages\aiogram\bot\bot.py", line 110, in get_updates
    result = await self.request(api.Methods.GET_UPDATES, payload)
             ^^^^^^^^^^^^^^^^^^^^^^^^^^^^^^^^^^^^^^^^^^^^^^^^^^^^
  File "D:\Python\Lib\site-packages\aiogram\bot\base.py", line 236, in request
    return await api.make_request(await self.get_session(), self.server, self.__token, method, data, files,
           ^^^^^^^^^^^^^^^^^^^^^^^^^^^^^^^^^^^^^^^^^^^^^^^^^^^^^^^^^^^^^^^^^^^^^^^^^^^^^^^^^^^^^^^^^^^^^^^^
  File "D:\Python\Lib\site-packages\aiogram\bot\api.py", line 140, in make_request
    return check_result(method, response.content_type, response.status, await response.text())
           ^^^^^^^^^^^^^^^^^^^^^^^^^^^^^^^^^^^^^^^^^^^^^^^^^^^^^^^^^^^^^^^^^^^^^^^^^^^^^^^^^^^
  File "D:\Python\Lib\site-packages\aiogram\bot\api.py", line 119, in check_result
    exceptions.ConflictError.detect(description)
  File "D:\Python\Lib\site-packages\aiogram\utils\exceptions.py", line 140, in detect
    raise err(cls.text or description)
aiogram.utils.exceptions.TerminatedByOtherGetUpdates: Terminated by other getupdates request; make sure that only one bot instance is running
2023-01-29 02:09:10,864 - ERROR -Task exception was never retrieved
future: <Task finished name='Task-11' coro=<Dispatcher._process_polling_updates() done, defined at D:\Python\Lib\site-packages\aiogram\dispatcher\dispatcher.py:407> exception=OperationalError('no such table: users')>
Traceback (most recent call last):
  File "D:\Python\Lib\site-packages\aiogram\dispatcher\dispatcher.py", line 415, in _process_polling_updates
    for responses in itertools.chain.from_iterable(await self.process_updates(updates, fast)):
                                                   ^^^^^^^^^^^^^^^^^^^^^^^^^^^^^^^^^^^^^^^^^
  File "D:\Python\Lib\site-packages\aiogram\dispatcher\dispatcher.py", line 235, in process_updates
    return await asyncio.gather(*tasks)
           ^^^^^^^^^^^^^^^^^^^^^^^^^^^^
  File "D:\Python\Lib\site-packages\aiogram\dispatcher\handler.py", line 117, in notify
    response = await handler_obj.handler(*args, **partial_data)
               ^^^^^^^^^^^^^^^^^^^^^^^^^^^^^^^^^^^^^^^^^^^^^^^^
  File "D:\Python\Lib\site-packages\aiogram\dispatcher\dispatcher.py", line 256, in process_update
    return await self.message_handlers.notify(update.message)
           ^^^^^^^^^^^^^^^^^^^^^^^^^^^^^^^^^^^^^^^^^^^^^^^^^^
  File "D:\Python\Lib\site-packages\aiogram\dispatcher\handler.py", line 117, in notify
    response = await handler_obj.handler(*args, **partial_data)
               ^^^^^^^^^^^^^^^^^^^^^^^^^^^^^^^^^^^^^^^^^^^^^^^^
  File "D:\ÒÅËÅÃĞÀÌÁÎÒÛ\ANONIMCHAT\main.py", line 60, in start
    count_users = KeyboardButton(f'Â áîòå óæå {int(db.count_user() * 1.5)} ïîëüçîâàòåëåé\U0001f973')
                                                   ^^^^^^^^^^^^^^^
  File "D:\ÒÅËÅÃĞÀÌÁÎÒÛ\ANONIMCHAT\database.py", line 82, in count_user
    result = self.cursor.execute('SELECT COUNT(*) FROM `users`').fetchone()
             ^^^^^^^^^^^^^^^^^^^^^^^^^^^^^^^^^^^^^^^^^^^^^^^^^^^
sqlite3.OperationalError: no such table: users
2023-01-29 02:09:12,506 - WARNING -no such table: users
2023-01-29 02:09:13,082 - WARNING -no such table: users
2023-01-29 02:09:13,167 - ERROR -Task exception was never retrieved
future: <Task finished name='Task-17' coro=<Dispatcher._process_polling_updates() done, defined at D:\Python\Lib\site-packages\aiogram\dispatcher\dispatcher.py:407> exception=ChatNotFound('Chat not found')>
Traceback (most recent call last):
  File "D:\ÒÅËÅÃĞÀÌÁÎÒÛ\ANONIMCHAT\main.py", line 250, in chating
    await bot.send_message(db.select_connect_with(message.from_user.id)[0],user_data['msg']) #îòïğàâëÿåì ñîîáùåíèÿ ïîëüçîâàòåëÿ
                           ^^^^^^^^^^^^^^^^^^^^^^^^^^^^^^^^^^^^^^^^^^^^
  File "D:\ÒÅËÅÃĞÀÌÁÎÒÛ\ANONIMCHAT\database.py", line 61, in select_connect_with
    return self.cursor.execute('SELECT `connect_with` FROM `users` WHERE `telegram_id` = ?',(telegram_id,)).fetchone()
           ^^^^^^^^^^^^^^^^^^^^^^^^^^^^^^^^^^^^^^^^^^^^^^^^^^^^^^^^^^^^^^^^^^^^^^^^^^^^^^^^^^^^^^^^^^^^^^^^
sqlite3.OperationalError: no such table: users

During handling of the above exception, another exception occurred:

Traceback (most recent call last):
  File "D:\Python\Lib\site-packages\aiogram\dispatcher\dispatcher.py", line 415, in _process_polling_updates
    for responses in itertools.chain.from_iterable(await self.process_updates(updates, fast)):
                                                   ^^^^^^^^^^^^^^^^^^^^^^^^^^^^^^^^^^^^^^^^^
  File "D:\Python\Lib\site-packages\aiogram\dispatcher\dispatcher.py", line 235, in process_updates
    return await asyncio.gather(*tasks)
           ^^^^^^^^^^^^^^^^^^^^^^^^^^^^
  File "D:\Python\Lib\site-packages\aiogram\dispatcher\handler.py", line 117, in notify
    response = await handler_obj.handler(*args, **partial_data)
               ^^^^^^^^^^^^^^^^^^^^^^^^^^^^^^^^^^^^^^^^^^^^^^^^
  File "D:\Python\Lib\site-packages\aiogram\dispatcher\dispatcher.py", line 256, in process_update
    return await self.message_handlers.notify(update.message)
           ^^^^^^^^^^^^^^^^^^^^^^^^^^^^^^^^^^^^^^^^^^^^^^^^^^
  File "D:\Python\Lib\site-packages\aiogram\dispatcher\handler.py", line 117, in notify
    response = await handler_obj.handler(*args, **partial_data)
               ^^^^^^^^^^^^^^^^^^^^^^^^^^^^^^^^^^^^^^^^^^^^^^^^
  File "D:\ÒÅËÅÃĞÀÌÁÎÒÛ\ANONIMCHAT\main.py", line 264, in chating
    await send_to_channel_log_exception(message,e)
  File "D:\ÒÅËÅÃĞÀÌÁÎÒÛ\ANONIMCHAT\main.py", line 302, in send_to_channel_log_exception
    await bot.send_message(-1001422742707,f'Îøèáêà\n\n{except_name}')
  File "D:\Python\Lib\site-packages\aiogram\bot\bot.py", line 346, in send_message
    result = await self.request(api.Methods.SEND_MESSAGE, payload)
             ^^^^^^^^^^^^^^^^^^^^^^^^^^^^^^^^^^^^^^^^^^^^^^^^^^^^^
  File "D:\Python\Lib\site-packages\aiogram\bot\base.py", line 236, in request
    return await api.make_request(await self.get_session(), self.server, self.__token, method, data, files,
           ^^^^^^^^^^^^^^^^^^^^^^^^^^^^^^^^^^^^^^^^^^^^^^^^^^^^^^^^^^^^^^^^^^^^^^^^^^^^^^^^^^^^^^^^^^^^^^^^
  File "D:\Python\Lib\site-packages\aiogram\bot\api.py", line 140, in make_request
    return check_result(method, response.content_type, response.status, await response.text())
           ^^^^^^^^^^^^^^^^^^^^^^^^^^^^^^^^^^^^^^^^^^^^^^^^^^^^^^^^^^^^^^^^^^^^^^^^^^^^^^^^^^^
  File "D:\Python\Lib\site-packages\aiogram\bot\api.py", line 115, in check_result
    exceptions.BadRequest.detect(description)
  File "D:\Python\Lib\site-packages\aiogram\utils\exceptions.py", line 140, in detect
    raise err(cls.text or description)
aiogram.utils.exceptions.ChatNotFound: Chat not found
2023-01-29 02:09:14,271 - ERROR -Cause exception while getting updates.
Traceback (most recent call last):
  File "D:\Python\Lib\site-packages\aiogram\dispatcher\dispatcher.py", line 381, in start_polling
    updates = await self.bot.get_updates(
              ^^^^^^^^^^^^^^^^^^^^^^^^^^^
  File "D:\Python\Lib\site-packages\aiogram\bot\bot.py", line 110, in get_updates
    result = await self.request(api.Methods.GET_UPDATES, payload)
             ^^^^^^^^^^^^^^^^^^^^^^^^^^^^^^^^^^^^^^^^^^^^^^^^^^^^
  File "D:\Python\Lib\site-packages\aiogram\bot\base.py", line 236, in request
    return await api.make_request(await self.get_session(), self.server, self.__token, method, data, files,
           ^^^^^^^^^^^^^^^^^^^^^^^^^^^^^^^^^^^^^^^^^^^^^^^^^^^^^^^^^^^^^^^^^^^^^^^^^^^^^^^^^^^^^^^^^^^^^^^^
  File "D:\Python\Lib\site-packages\aiogram\bot\api.py", line 140, in make_request
    return check_result(method, response.content_type, response.status, await response.text())
           ^^^^^^^^^^^^^^^^^^^^^^^^^^^^^^^^^^^^^^^^^^^^^^^^^^^^^^^^^^^^^^^^^^^^^^^^^^^^^^^^^^^
  File "D:\Python\Lib\site-packages\aiogram\bot\api.py", line 119, in check_result
    exceptions.ConflictError.detect(description)
  File "D:\Python\Lib\site-packages\aiogram\utils\exceptions.py", line 140, in detect
    raise err(cls.text or description)
aiogram.utils.exceptions.TerminatedByOtherGetUpdates: Terminated by other getupdates request; make sure that only one bot instance is running
2023-01-29 02:09:20,415 - ERROR -Task exception was never retrieved
future: <Task finished name='Task-26' coro=<Dispatcher._process_polling_updates() done, defined at D:\Python\Lib\site-packages\aiogram\dispatcher\dispatcher.py:407> exception=OperationalError('no such table: users')>
Traceback (most recent call last):
  File "D:\Python\Lib\site-packages\aiogram\dispatcher\dispatcher.py", line 415, in _process_polling_updates
    for responses in itertools.chain.from_iterable(await self.process_updates(updates, fast)):
                                                   ^^^^^^^^^^^^^^^^^^^^^^^^^^^^^^^^^^^^^^^^^
  File "D:\Python\Lib\site-packages\aiogram\dispatcher\dispatcher.py", line 235, in process_updates
    return await asyncio.gather(*tasks)
           ^^^^^^^^^^^^^^^^^^^^^^^^^^^^
  File "D:\Python\Lib\site-packages\aiogram\dispatcher\handler.py", line 117, in notify
    response = await handler_obj.handler(*args, **partial_data)
               ^^^^^^^^^^^^^^^^^^^^^^^^^^^^^^^^^^^^^^^^^^^^^^^^
  File "D:\Python\Lib\site-packages\aiogram\dispatcher\dispatcher.py", line 256, in process_update
    return await self.message_handlers.notify(update.message)
           ^^^^^^^^^^^^^^^^^^^^^^^^^^^^^^^^^^^^^^^^^^^^^^^^^^
  File "D:\Python\Lib\site-packages\aiogram\dispatcher\handler.py", line 117, in notify
    response = await handler_obj.handler(*args, **partial_data)
               ^^^^^^^^^^^^^^^^^^^^^^^^^^^^^^^^^^^^^^^^^^^^^^^^
  File "D:\ÒÅËÅÃĞÀÌÁÎÒÛ\ANONIMCHAT\main.py", line 60, in start
    count_users = KeyboardButton(f'Â áîòå óæå {int(db.count_user() * 1.5)} ïîëüçîâàòåëåé\U0001f973')
                                                   ^^^^^^^^^^^^^^^
  File "D:\ÒÅËÅÃĞÀÌÁÎÒÛ\ANONIMCHAT\database.py", line 82, in count_user
    result = self.cursor.execute('SELECT COUNT(*) FROM `users`').fetchone()
             ^^^^^^^^^^^^^^^^^^^^^^^^^^^^^^^^^^^^^^^^^^^^^^^^^^^
sqlite3.OperationalError: no such table: users
2023-01-29 02:09:21,615 - ERROR -Task exception was never retrieved
future: <Task finished name='Task-29' coro=<Dispatcher._process_polling_updates() done, defined at D:\Python\Lib\site-packages\aiogram\dispatcher\dispatcher.py:407> exception=OperationalError('no such table: users')>
Traceback (most recent call last):
  File "D:\Python\Lib\site-packages\aiogram\dispatcher\dispatcher.py", line 415, in _process_polling_updates
    for responses in itertools.chain.from_iterable(await self.process_updates(updates, fast)):
                                                   ^^^^^^^^^^^^^^^^^^^^^^^^^^^^^^^^^^^^^^^^^
  File "D:\Python\Lib\site-packages\aiogram\dispatcher\dispatcher.py", line 235, in process_updates
    return await asyncio.gather(*tasks)
           ^^^^^^^^^^^^^^^^^^^^^^^^^^^^
  File "D:\Python\Lib\site-packages\aiogram\dispatcher\handler.py", line 117, in notify
    response = await handler_obj.handler(*args, **partial_data)
               ^^^^^^^^^^^^^^^^^^^^^^^^^^^^^^^^^^^^^^^^^^^^^^^^
  File "D:\Python\Lib\site-packages\aiogram\dispatcher\dispatcher.py", line 256, in process_update
    return await self.message_handlers.notify(update.message)
           ^^^^^^^^^^^^^^^^^^^^^^^^^^^^^^^^^^^^^^^^^^^^^^^^^^
  File "D:\Python\Lib\site-packages\aiogram\dispatcher\handler.py", line 117, in notify
    response = await handler_obj.handler(*args, **partial_data)
               ^^^^^^^^^^^^^^^^^^^^^^^^^^^^^^^^^^^^^^^^^^^^^^^^
  File "D:\ÒÅËÅÃĞÀÌÁÎÒÛ\ANONIMCHAT\main.py", line 60, in start
    count_users = KeyboardButton(f'Â áîòå óæå {int(db.count_user() * 1.5)} ïîëüçîâàòåëåé\U0001f973')
                                                   ^^^^^^^^^^^^^^^
  File "D:\ÒÅËÅÃĞÀÌÁÎÒÛ\ANONIMCHAT\database.py", line 82, in count_user
    result = self.cursor.execute('SELECT COUNT(*) FROM `users`').fetchone()
             ^^^^^^^^^^^^^^^^^^^^^^^^^^^^^^^^^^^^^^^^^^^^^^^^^^^
sqlite3.OperationalError: no such table: users
2023-01-29 02:09:22,689 - ERROR -Task exception was never retrieved
future: <Task finished name='Task-32' coro=<Dispatcher._process_polling_updates() done, defined at D:\Python\Lib\site-packages\aiogram\dispatcher\dispatcher.py:407> exception=OperationalError('no such table: users')>
Traceback (most recent call last):
  File "D:\Python\Lib\site-packages\aiogram\dispatcher\dispatcher.py", line 415, in _process_polling_updates
    for responses in itertools.chain.from_iterable(await self.process_updates(updates, fast)):
                                                   ^^^^^^^^^^^^^^^^^^^^^^^^^^^^^^^^^^^^^^^^^
  File "D:\Python\Lib\site-packages\aiogram\dispatcher\dispatcher.py", line 235, in process_updates
    return await asyncio.gather(*tasks)
           ^^^^^^^^^^^^^^^^^^^^^^^^^^^^
  File "D:\Python\Lib\site-packages\aiogram\dispatcher\handler.py", line 117, in notify
    response = await handler_obj.handler(*args, **partial_data)
               ^^^^^^^^^^^^^^^^^^^^^^^^^^^^^^^^^^^^^^^^^^^^^^^^
  File "D:\Python\Lib\site-packages\aiogram\dispatcher\dispatcher.py", line 256, in process_update
    return await self.message_handlers.notify(update.message)
           ^^^^^^^^^^^^^^^^^^^^^^^^^^^^^^^^^^^^^^^^^^^^^^^^^^
  File "D:\Python\Lib\site-packages\aiogram\dispatcher\handler.py", line 117, in notify
    response = await handler_obj.handler(*args, **partial_data)
               ^^^^^^^^^^^^^^^^^^^^^^^^^^^^^^^^^^^^^^^^^^^^^^^^
  File "D:\ÒÅËÅÃĞÀÌÁÎÒÛ\ANONIMCHAT\main.py", line 60, in start
    count_users = KeyboardButton(f'Â áîòå óæå {int(db.count_user() * 1.5)} ïîëüçîâàòåëåé\U0001f973')
                                                   ^^^^^^^^^^^^^^^
  File "D:\ÒÅËÅÃĞÀÌÁÎÒÛ\ANONIMCHAT\database.py", line 82, in count_user
    result = self.cursor.execute('SELECT COUNT(*) FROM `users`').fetchone()
             ^^^^^^^^^^^^^^^^^^^^^^^^^^^^^^^^^^^^^^^^^^^^^^^^^^^
sqlite3.OperationalError: no such table: users
2023-01-29 02:09:23,702 - WARNING -no such table: users
2023-01-29 02:09:23,941 - WARNING -no such table: users
2023-01-29 02:09:24,122 - WARNING -no such table: users
2023-01-29 02:09:24,301 - WARNING -no such table: users
2023-01-29 02:09:24,473 - WARNING -no such table: users
2023-01-29 02:09:29,678 - ERROR -Cause exception while getting updates.
Traceback (most recent call last):
  File "D:\Python\Lib\site-packages\aiogram\dispatcher\dispatcher.py", line 381, in start_polling
    updates = await self.bot.get_updates(
              ^^^^^^^^^^^^^^^^^^^^^^^^^^^
  File "D:\Python\Lib\site-packages\aiogram\bot\bot.py", line 110, in get_updates
    result = await self.request(api.Methods.GET_UPDATES, payload)
             ^^^^^^^^^^^^^^^^^^^^^^^^^^^^^^^^^^^^^^^^^^^^^^^^^^^^
  File "D:\Python\Lib\site-packages\aiogram\bot\base.py", line 236, in request
    return await api.make_request(await self.get_session(), self.server, self.__token, method, data, files,
           ^^^^^^^^^^^^^^^^^^^^^^^^^^^^^^^^^^^^^^^^^^^^^^^^^^^^^^^^^^^^^^^^^^^^^^^^^^^^^^^^^^^^^^^^^^^^^^^^
  File "D:\Python\Lib\site-packages\aiogram\bot\api.py", line 140, in make_request
    return check_result(method, response.content_type, response.status, await response.text())
           ^^^^^^^^^^^^^^^^^^^^^^^^^^^^^^^^^^^^^^^^^^^^^^^^^^^^^^^^^^^^^^^^^^^^^^^^^^^^^^^^^^^
  File "D:\Python\Lib\site-packages\aiogram\bot\api.py", line 119, in check_result
    exceptions.ConflictError.detect(description)
  File "D:\Python\Lib\site-packages\aiogram\utils\exceptions.py", line 140, in detect
    raise err(cls.text or description)
aiogram.utils.exceptions.TerminatedByOtherGetUpdates: Terminated by other getupdates request; make sure that only one bot instance is running
2023-01-29 02:09:36,289 - ERROR -Task exception was never retrieved
future: <Task finished name='Task-51' coro=<Dispatcher._process_polling_updates() done, defined at D:\Python\Lib\site-packages\aiogram\dispatcher\dispatcher.py:407> exception=OperationalError('no such table: users')>
Traceback (most recent call last):
  File "D:\Python\Lib\site-packages\aiogram\dispatcher\dispatcher.py", line 415, in _process_polling_updates
    for responses in itertools.chain.from_iterable(await self.process_updates(updates, fast)):
                                                   ^^^^^^^^^^^^^^^^^^^^^^^^^^^^^^^^^^^^^^^^^
  File "D:\Python\Lib\site-packages\aiogram\dispatcher\dispatcher.py", line 235, in process_updates
    return await asyncio.gather(*tasks)
           ^^^^^^^^^^^^^^^^^^^^^^^^^^^^
  File "D:\Python\Lib\site-packages\aiogram\dispatcher\handler.py", line 117, in notify
    response = await handler_obj.handler(*args, **partial_data)
               ^^^^^^^^^^^^^^^^^^^^^^^^^^^^^^^^^^^^^^^^^^^^^^^^
  File "D:\Python\Lib\site-packages\aiogram\dispatcher\dispatcher.py", line 256, in process_update
    return await self.message_handlers.notify(update.message)
           ^^^^^^^^^^^^^^^^^^^^^^^^^^^^^^^^^^^^^^^^^^^^^^^^^^
  File "D:\Python\Lib\site-packages\aiogram\dispatcher\handler.py", line 117, in notify
    response = await handler_obj.handler(*args, **partial_data)
               ^^^^^^^^^^^^^^^^^^^^^^^^^^^^^^^^^^^^^^^^^^^^^^^^
  File "D:\ÒÅËÅÃĞÀÌÁÎÒÛ\ANONIMCHAT\main.py", line 60, in start
    count_users = KeyboardButton(f'Â áîòå óæå {int(db.count_user() * 1.5)} ïîëüçîâàòåëåé\U0001f973')
                                                   ^^^^^^^^^^^^^^^
  File "D:\ÒÅËÅÃĞÀÌÁÎÒÛ\ANONIMCHAT\database.py", line 82, in count_user
    result = self.cursor.execute('SELECT COUNT(*) FROM `users`').fetchone()
             ^^^^^^^^^^^^^^^^^^^^^^^^^^^^^^^^^^^^^^^^^^^^^^^^^^^
sqlite3.OperationalError: no such table: users
2023-01-29 02:09:48,890 - INFO -Bot: Àíîíèìíûé ×àò [@anonimchatarcher_bot]
2023-01-29 02:09:49,025 - WARNING -Updates were skipped successfully.
2023-01-29 02:09:49,027 - INFO -Start polling.
2023-01-29 02:09:57,220 - ERROR -Task exception was never retrieved
future: <Task finished name='Task-9' coro=<Dispatcher._process_polling_updates() done, defined at D:\Python\Lib\site-packages\aiogram\dispatcher\dispatcher.py:407> exception=OperationalError('no such table: users')>
Traceback (most recent call last):
  File "D:\Python\Lib\site-packages\aiogram\dispatcher\dispatcher.py", line 415, in _process_polling_updates
    for responses in itertools.chain.from_iterable(await self.process_updates(updates, fast)):
                                                   ^^^^^^^^^^^^^^^^^^^^^^^^^^^^^^^^^^^^^^^^^
  File "D:\Python\Lib\site-packages\aiogram\dispatcher\dispatcher.py", line 235, in process_updates
    return await asyncio.gather(*tasks)
           ^^^^^^^^^^^^^^^^^^^^^^^^^^^^
  File "D:\Python\Lib\site-packages\aiogram\dispatcher\handler.py", line 117, in notify
    response = await handler_obj.handler(*args, **partial_data)
               ^^^^^^^^^^^^^^^^^^^^^^^^^^^^^^^^^^^^^^^^^^^^^^^^
  File "D:\Python\Lib\site-packages\aiogram\dispatcher\dispatcher.py", line 256, in process_update
    return await self.message_handlers.notify(update.message)
           ^^^^^^^^^^^^^^^^^^^^^^^^^^^^^^^^^^^^^^^^^^^^^^^^^^
  File "D:\Python\Lib\site-packages\aiogram\dispatcher\handler.py", line 117, in notify
    response = await handler_obj.handler(*args, **partial_data)
               ^^^^^^^^^^^^^^^^^^^^^^^^^^^^^^^^^^^^^^^^^^^^^^^^
  File "D:\ÒÅËÅÃĞÀÌÁÎÒÛ\ANONIMCHAT\main.py", line 60, in start
    count_users = KeyboardButton(f'Â áîòå óæå {int(db.count_user() * 1.5)} ïîëüçîâàòåëåé\U0001f973')
                                                   ^^^^^^^^^^^^^^^
  File "D:\ÒÅËÅÃĞÀÌÁÎÒÛ\ANONIMCHAT\database.py", line 82, in count_user
    result = self.cursor.execute('SELECT COUNT(*) FROM `users`').fetchone()
             ^^^^^^^^^^^^^^^^^^^^^^^^^^^^^^^^^^^^^^^^^^^^^^^^^^^
sqlite3.OperationalError: no such table: users
2023-01-29 02:09:59,192 - WARNING -no such table: users
2023-01-29 02:10:04,204 - WARNING -no such table: users
2023-01-29 02:10:04,636 - WARNING -no such table: users
2023-01-29 02:10:04,711 - ERROR -Task exception was never retrieved
future: <Task finished name='Task-26' coro=<Dispatcher._process_polling_updates() done, defined at D:\Python\Lib\site-packages\aiogram\dispatcher\dispatcher.py:407> exception=ChatNotFound('Chat not found')>
Traceback (most recent call last):
  File "D:\ÒÅËÅÃĞÀÌÁÎÒÛ\ANONIMCHAT\main.py", line 250, in chating
    await bot.send_message(db.select_connect_with(message.from_user.id)[0],user_data['msg']) #îòïğàâëÿåì ñîîáùåíèÿ ïîëüçîâàòåëÿ
                           ^^^^^^^^^^^^^^^^^^^^^^^^^^^^^^^^^^^^^^^^^^^^
  File "D:\ÒÅËÅÃĞÀÌÁÎÒÛ\ANONIMCHAT\database.py", line 61, in select_connect_with
    return self.cursor.execute('SELECT `connect_with` FROM `users` WHERE `telegram_id` = ?',(telegram_id,)).fetchone()
           ^^^^^^^^^^^^^^^^^^^^^^^^^^^^^^^^^^^^^^^^^^^^^^^^^^^^^^^^^^^^^^^^^^^^^^^^^^^^^^^^^^^^^^^^^^^^^^^^
sqlite3.OperationalError: no such table: users

During handling of the above exception, another exception occurred:

Traceback (most recent call last):
  File "D:\Python\Lib\site-packages\aiogram\dispatcher\dispatcher.py", line 415, in _process_polling_updates
    for responses in itertools.chain.from_iterable(await self.process_updates(updates, fast)):
                                                   ^^^^^^^^^^^^^^^^^^^^^^^^^^^^^^^^^^^^^^^^^
  File "D:\Python\Lib\site-packages\aiogram\dispatcher\dispatcher.py", line 235, in process_updates
    return await asyncio.gather(*tasks)
           ^^^^^^^^^^^^^^^^^^^^^^^^^^^^
  File "D:\Python\Lib\site-packages\aiogram\dispatcher\handler.py", line 117, in notify
    response = await handler_obj.handler(*args, **partial_data)
               ^^^^^^^^^^^^^^^^^^^^^^^^^^^^^^^^^^^^^^^^^^^^^^^^
  File "D:\Python\Lib\site-packages\aiogram\dispatcher\dispatcher.py", line 256, in process_update
    return await self.message_handlers.notify(update.message)
           ^^^^^^^^^^^^^^^^^^^^^^^^^^^^^^^^^^^^^^^^^^^^^^^^^^
  File "D:\Python\Lib\site-packages\aiogram\dispatcher\handler.py", line 117, in notify
    response = await handler_obj.handler(*args, **partial_data)
               ^^^^^^^^^^^^^^^^^^^^^^^^^^^^^^^^^^^^^^^^^^^^^^^^
  File "D:\ÒÅËÅÃĞÀÌÁÎÒÛ\ANONIMCHAT\main.py", line 264, in chating
    await send_to_channel_log_exception(message,e)
  File "D:\ÒÅËÅÃĞÀÌÁÎÒÛ\ANONIMCHAT\main.py", line 302, in send_to_channel_log_exception
    await bot.send_message(-1001422742707,f'Îøèáêà\n\n{except_name}')
  File "D:\Python\Lib\site-packages\aiogram\bot\bot.py", line 346, in send_message
    result = await self.request(api.Methods.SEND_MESSAGE, payload)
             ^^^^^^^^^^^^^^^^^^^^^^^^^^^^^^^^^^^^^^^^^^^^^^^^^^^^^
  File "D:\Python\Lib\site-packages\aiogram\bot\base.py", line 236, in request
    return await api.make_request(await self.get_session(), self.server, self.__token, method, data, files,
           ^^^^^^^^^^^^^^^^^^^^^^^^^^^^^^^^^^^^^^^^^^^^^^^^^^^^^^^^^^^^^^^^^^^^^^^^^^^^^^^^^^^^^^^^^^^^^^^^
  File "D:\Python\Lib\site-packages\aiogram\bot\api.py", line 140, in make_request
    return check_result(method, response.content_type, response.status, await response.text())
           ^^^^^^^^^^^^^^^^^^^^^^^^^^^^^^^^^^^^^^^^^^^^^^^^^^^^^^^^^^^^^^^^^^^^^^^^^^^^^^^^^^^
  File "D:\Python\Lib\site-packages\aiogram\bot\api.py", line 115, in check_result
    exceptions.BadRequest.detect(description)
  File "D:\Python\Lib\site-packages\aiogram\utils\exceptions.py", line 140, in detect
    raise err(cls.text or description)
aiogram.utils.exceptions.ChatNotFound: Chat not found
2023-01-29 02:10:06,100 - WARNING -no such table: users
2023-01-29 02:10:06,288 - WARNING -no such table: users
2023-01-29 02:10:06,456 - WARNING -no such table: users
2023-01-29 02:10:06,637 - WARNING -no such table: users
2023-01-29 02:10:20,341 - WARNING -no such table: users
2023-01-29 02:10:23,003 - WARNING -no such table: users
