2023-01-08 22:34:30,725 - INFO -Bot: Çíàêîìñòâà [@datingarcher_bot]
2023-01-08 22:34:30,835 - WARNING -Updates were skipped successfully.
2023-01-08 22:34:30,835 - INFO -Start polling.
2023-01-08 22:34:38,664 - ERROR -Task exception was never retrieved
future: <Task finished name='Task-9' coro=<Dispatcher._process_polling_updates() done, defined at D:\Python\Lib\site-packages\aiogram\dispatcher\dispatcher.py:407> exception=OperationalError('no such table: users')>
Traceback (most recent call last):
  File "D:\Python\Lib\site-packages\aiogram\dispatcher\dispatcher.py", line 415, in _process_polling_updates
    for responses in itertools.chain.from_iterable(await self.process_updates(updates, fast)):
                                                   ^^^^^^^^^^^^^^^^^^^^^^^^^^^^^^^^^^^^^^^^^
  File "D:\Python\Lib\site-packages\aiogram\dispatcher\dispatcher.py", line 235, in process_updates
    return await asyncio.gather(*tasks)
           ^^^^^^^^^^^^^^^^^^^^^^^^^^^^
  File "D:\Python\Lib\site-packages\aiogram\dispatcher\handler.py", line 117, in notify
    response = await handler_obj.handler(*args, **partial_data)
               ^^^^^^^^^^^^^^^^^^^^^^^^^^^^^^^^^^^^^^^^^^^^^^^^
  File "D:\Python\Lib\site-packages\aiogram\dispatcher\dispatcher.py", line 256, in process_update
    return await self.message_handlers.notify(update.message)
           ^^^^^^^^^^^^^^^^^^^^^^^^^^^^^^^^^^^^^^^^^^^^^^^^^^
  File "D:\Python\Lib\site-packages\aiogram\dispatcher\handler.py", line 117, in notify
    response = await handler_obj.handler(*args, **partial_data)
               ^^^^^^^^^^^^^^^^^^^^^^^^^^^^^^^^^^^^^^^^^^^^^^^^
  File "D:\ÒÅËÅÃĞÀÌÁÎÒÛ\AnonymChat\main.py", line 60, in start
    count_users = KeyboardButton(f'Â áîòå óæå {int(db.count_user() * 1.5)} ïîëüçîâàòåëåé\U0001f973')
                                                   ^^^^^^^^^^^^^^^
  File "D:\ÒÅËÅÃĞÀÌÁÎÒÛ\AnonymChat\database.py", line 82, in count_user
    result = self.cursor.execute('SELECT COUNT(*) FROM `users`').fetchone()
             ^^^^^^^^^^^^^^^^^^^^^^^^^^^^^^^^^^^^^^^^^^^^^^^^^^^
sqlite3.OperationalError: no such table: users
2023-01-08 22:34:44,087 - WARNING -no such table: users
2023-01-08 22:34:44,259 - ERROR -Task exception was never retrieved
future: <Task finished name='Task-12' coro=<Dispatcher._process_polling_updates() done, defined at D:\Python\Lib\site-packages\aiogram\dispatcher\dispatcher.py:407> exception=ChatNotFound('Chat not found')>
Traceback (most recent call last):
  File "D:\ÒÅËÅÃĞÀÌÁÎÒÛ\AnonymChat\main.py", line 250, in chating
    await bot.send_message(db.select_connect_with(message.from_user.id)[0],user_data['msg']) #îòïğàâëÿåì ñîîáùåíèÿ ïîëüçîâàòåëÿ
                           ^^^^^^^^^^^^^^^^^^^^^^^^^^^^^^^^^^^^^^^^^^^^
  File "D:\ÒÅËÅÃĞÀÌÁÎÒÛ\AnonymChat\database.py", line 61, in select_connect_with
    return self.cursor.execute('SELECT `connect_with` FROM `users` WHERE `telegram_id` = ?',(telegram_id,)).fetchone()
           ^^^^^^^^^^^^^^^^^^^^^^^^^^^^^^^^^^^^^^^^^^^^^^^^^^^^^^^^^^^^^^^^^^^^^^^^^^^^^^^^^^^^^^^^^^^^^^^^
sqlite3.OperationalError: no such table: users

During handling of the above exception, another exception occurred:

Traceback (most recent call last):
  File "D:\Python\Lib\site-packages\aiogram\dispatcher\dispatcher.py", line 415, in _process_polling_updates
    for responses in itertools.chain.from_iterable(await self.process_updates(updates, fast)):
                                                   ^^^^^^^^^^^^^^^^^^^^^^^^^^^^^^^^^^^^^^^^^
  File "D:\Python\Lib\site-packages\aiogram\dispatcher\dispatcher.py", line 235, in process_updates
    return await asyncio.gather(*tasks)
           ^^^^^^^^^^^^^^^^^^^^^^^^^^^^
  File "D:\Python\Lib\site-packages\aiogram\dispatcher\handler.py", line 117, in notify
    response = await handler_obj.handler(*args, **partial_data)
               ^^^^^^^^^^^^^^^^^^^^^^^^^^^^^^^^^^^^^^^^^^^^^^^^
  File "D:\Python\Lib\site-packages\aiogram\dispatcher\dispatcher.py", line 256, in process_update
    return await self.message_handlers.notify(update.message)
           ^^^^^^^^^^^^^^^^^^^^^^^^^^^^^^^^^^^^^^^^^^^^^^^^^^
  File "D:\Python\Lib\site-packages\aiogram\dispatcher\handler.py", line 117, in notify
    response = await handler_obj.handler(*args, **partial_data)
               ^^^^^^^^^^^^^^^^^^^^^^^^^^^^^^^^^^^^^^^^^^^^^^^^
  File "D:\ÒÅËÅÃĞÀÌÁÎÒÛ\AnonymChat\main.py", line 264, in chating
    await send_to_channel_log_exception(message,e)
  File "D:\ÒÅËÅÃĞÀÌÁÎÒÛ\AnonymChat\main.py", line 302, in send_to_channel_log_exception
    await bot.send_message(-1001422742707,f'Îøèáêà\n\n{except_name}')
  File "D:\Python\Lib\site-packages\aiogram\bot\bot.py", line 346, in send_message
    result = await self.request(api.Methods.SEND_MESSAGE, payload)
             ^^^^^^^^^^^^^^^^^^^^^^^^^^^^^^^^^^^^^^^^^^^^^^^^^^^^^
  File "D:\Python\Lib\site-packages\aiogram\bot\base.py", line 236, in request
    return await api.make_request(await self.get_session(), self.server, self.__token, method, data, files,
           ^^^^^^^^^^^^^^^^^^^^^^^^^^^^^^^^^^^^^^^^^^^^^^^^^^^^^^^^^^^^^^^^^^^^^^^^^^^^^^^^^^^^^^^^^^^^^^^^
  File "D:\Python\Lib\site-packages\aiogram\bot\api.py", line 140, in make_request
    return check_result(method, response.content_type, response.status, await response.text())
           ^^^^^^^^^^^^^^^^^^^^^^^^^^^^^^^^^^^^^^^^^^^^^^^^^^^^^^^^^^^^^^^^^^^^^^^^^^^^^^^^^^^
  File "D:\Python\Lib\site-packages\aiogram\bot\api.py", line 115, in check_result
    exceptions.BadRequest.detect(description)
  File "D:\Python\Lib\site-packages\aiogram\utils\exceptions.py", line 140, in detect
    raise err(cls.text or description)
aiogram.utils.exceptions.ChatNotFound: Chat not found
2023-01-08 22:34:45,346 - ERROR -Task exception was never retrieved
future: <Task finished name='Task-17' coro=<Dispatcher._process_polling_updates() done, defined at D:\Python\Lib\site-packages\aiogram\dispatcher\dispatcher.py:407> exception=OperationalError('no such table: users')>
Traceback (most recent call last):
  File "D:\Python\Lib\site-packages\aiogram\dispatcher\dispatcher.py", line 415, in _process_polling_updates
    for responses in itertools.chain.from_iterable(await self.process_updates(updates, fast)):
                                                   ^^^^^^^^^^^^^^^^^^^^^^^^^^^^^^^^^^^^^^^^^
  File "D:\Python\Lib\site-packages\aiogram\dispatcher\dispatcher.py", line 235, in process_updates
    return await asyncio.gather(*tasks)
           ^^^^^^^^^^^^^^^^^^^^^^^^^^^^
  File "D:\Python\Lib\site-packages\aiogram\dispatcher\handler.py", line 117, in notify
    response = await handler_obj.handler(*args, **partial_data)
               ^^^^^^^^^^^^^^^^^^^^^^^^^^^^^^^^^^^^^^^^^^^^^^^^
  File "D:\Python\Lib\site-packages\aiogram\dispatcher\dispatcher.py", line 256, in process_update
    return await self.message_handlers.notify(update.message)
           ^^^^^^^^^^^^^^^^^^^^^^^^^^^^^^^^^^^^^^^^^^^^^^^^^^
  File "D:\Python\Lib\site-packages\aiogram\dispatcher\handler.py", line 117, in notify
    response = await handler_obj.handler(*args, **partial_data)
               ^^^^^^^^^^^^^^^^^^^^^^^^^^^^^^^^^^^^^^^^^^^^^^^^
  File "D:\ÒÅËÅÃĞÀÌÁÎÒÛ\AnonymChat\main.py", line 60, in start
    count_users = KeyboardButton(f'Â áîòå óæå {int(db.count_user() * 1.5)} ïîëüçîâàòåëåé\U0001f973')
                                                   ^^^^^^^^^^^^^^^
  File "D:\ÒÅËÅÃĞÀÌÁÎÒÛ\AnonymChat\database.py", line 82, in count_user
    result = self.cursor.execute('SELECT COUNT(*) FROM `users`').fetchone()
             ^^^^^^^^^^^^^^^^^^^^^^^^^^^^^^^^^^^^^^^^^^^^^^^^^^^
sqlite3.OperationalError: no such table: users
2023-01-08 22:34:46,178 - ERROR -Task exception was never retrieved
future: <Task finished name='Task-20' coro=<Dispatcher._process_polling_updates() done, defined at D:\Python\Lib\site-packages\aiogram\dispatcher\dispatcher.py:407> exception=OperationalError('no such table: users')>
Traceback (most recent call last):
  File "D:\Python\Lib\site-packages\aiogram\dispatcher\dispatcher.py", line 415, in _process_polling_updates
    for responses in itertools.chain.from_iterable(await self.process_updates(updates, fast)):
                                                   ^^^^^^^^^^^^^^^^^^^^^^^^^^^^^^^^^^^^^^^^^
  File "D:\Python\Lib\site-packages\aiogram\dispatcher\dispatcher.py", line 235, in process_updates
    return await asyncio.gather(*tasks)
           ^^^^^^^^^^^^^^^^^^^^^^^^^^^^
  File "D:\Python\Lib\site-packages\aiogram\dispatcher\handler.py", line 117, in notify
    response = await handler_obj.handler(*args, **partial_data)
               ^^^^^^^^^^^^^^^^^^^^^^^^^^^^^^^^^^^^^^^^^^^^^^^^
  File "D:\Python\Lib\site-packages\aiogram\dispatcher\dispatcher.py", line 256, in process_update
    return await self.message_handlers.notify(update.message)
           ^^^^^^^^^^^^^^^^^^^^^^^^^^^^^^^^^^^^^^^^^^^^^^^^^^
  File "D:\Python\Lib\site-packages\aiogram\dispatcher\handler.py", line 117, in notify
    response = await handler_obj.handler(*args, **partial_data)
               ^^^^^^^^^^^^^^^^^^^^^^^^^^^^^^^^^^^^^^^^^^^^^^^^
  File "D:\ÒÅËÅÃĞÀÌÁÎÒÛ\AnonymChat\main.py", line 60, in start
    count_users = KeyboardButton(f'Â áîòå óæå {int(db.count_user() * 1.5)} ïîëüçîâàòåëåé\U0001f973')
                                                   ^^^^^^^^^^^^^^^
  File "D:\ÒÅËÅÃĞÀÌÁÎÒÛ\AnonymChat\database.py", line 82, in count_user
    result = self.cursor.execute('SELECT COUNT(*) FROM `users`').fetchone()
             ^^^^^^^^^^^^^^^^^^^^^^^^^^^^^^^^^^^^^^^^^^^^^^^^^^^
sqlite3.OperationalError: no such table: users
2023-01-29 02:10:54,182 - INFO -Bot: Àíîíèìíûé ×àò [@anonimchatarcher_bot]
2023-01-29 02:10:54,316 - WARNING -Updates were skipped successfully.
2023-01-29 02:10:54,317 - INFO -Start polling.
2023-01-29 02:11:02,112 - ERROR -Task exception was never retrieved
future: <Task finished name='Task-9' coro=<Dispatcher._process_polling_updates() done, defined at D:\Python\Lib\site-packages\aiogram\dispatcher\dispatcher.py:407> exception=OperationalError('no such table: users')>
Traceback (most recent call last):
  File "D:\Python\Lib\site-packages\aiogram\dispatcher\dispatcher.py", line 415, in _process_polling_updates
    for responses in itertools.chain.from_iterable(await self.process_updates(updates, fast)):
                                                   ^^^^^^^^^^^^^^^^^^^^^^^^^^^^^^^^^^^^^^^^^
  File "D:\Python\Lib\site-packages\aiogram\dispatcher\dispatcher.py", line 235, in process_updates
    return await asyncio.gather(*tasks)
           ^^^^^^^^^^^^^^^^^^^^^^^^^^^^
  File "D:\Python\Lib\site-packages\aiogram\dispatcher\handler.py", line 117, in notify
    response = await handler_obj.handler(*args, **partial_data)
               ^^^^^^^^^^^^^^^^^^^^^^^^^^^^^^^^^^^^^^^^^^^^^^^^
  File "D:\Python\Lib\site-packages\aiogram\dispatcher\dispatcher.py", line 256, in process_update
    return await self.message_handlers.notify(update.message)
           ^^^^^^^^^^^^^^^^^^^^^^^^^^^^^^^^^^^^^^^^^^^^^^^^^^
  File "D:\Python\Lib\site-packages\aiogram\dispatcher\handler.py", line 117, in notify
    response = await handler_obj.handler(*args, **partial_data)
               ^^^^^^^^^^^^^^^^^^^^^^^^^^^^^^^^^^^^^^^^^^^^^^^^
  File "D:\ÒÅËÅÃĞÀÌÁÎÒÛ\AnonymChat\main.py", line 60, in start
    count_users = KeyboardButton(f'Â áîòå óæå {int(db.count_user() * 1.5)} ïîëüçîâàòåëåé\U0001f973')
                                                   ^^^^^^^^^^^^^^^
  File "D:\ÒÅËÅÃĞÀÌÁÎÒÛ\AnonymChat\database.py", line 82, in count_user
    result = self.cursor.execute('SELECT COUNT(*) FROM `users`').fetchone()
             ^^^^^^^^^^^^^^^^^^^^^^^^^^^^^^^^^^^^^^^^^^^^^^^^^^^
sqlite3.OperationalError: no such table: users
2023-01-29 02:11:17,574 - ERROR -Task exception was never retrieved
future: <Task finished name='Task-12' coro=<Dispatcher._process_polling_updates() done, defined at D:\Python\Lib\site-packages\aiogram\dispatcher\dispatcher.py:407> exception=OperationalError('no such table: users')>
Traceback (most recent call last):
  File "D:\Python\Lib\site-packages\aiogram\dispatcher\dispatcher.py", line 415, in _process_polling_updates
    for responses in itertools.chain.from_iterable(await self.process_updates(updates, fast)):
                                                   ^^^^^^^^^^^^^^^^^^^^^^^^^^^^^^^^^^^^^^^^^
  File "D:\Python\Lib\site-packages\aiogram\dispatcher\dispatcher.py", line 235, in process_updates
    return await asyncio.gather(*tasks)
           ^^^^^^^^^^^^^^^^^^^^^^^^^^^^
  File "D:\Python\Lib\site-packages\aiogram\dispatcher\handler.py", line 117, in notify
    response = await handler_obj.handler(*args, **partial_data)
               ^^^^^^^^^^^^^^^^^^^^^^^^^^^^^^^^^^^^^^^^^^^^^^^^
  File "D:\Python\Lib\site-packages\aiogram\dispatcher\dispatcher.py", line 256, in process_update
    return await self.message_handlers.notify(update.message)
           ^^^^^^^^^^^^^^^^^^^^^^^^^^^^^^^^^^^^^^^^^^^^^^^^^^
  File "D:\Python\Lib\site-packages\aiogram\dispatcher\handler.py", line 117, in notify
    response = await handler_obj.handler(*args, **partial_data)
               ^^^^^^^^^^^^^^^^^^^^^^^^^^^^^^^^^^^^^^^^^^^^^^^^
  File "D:\ÒÅËÅÃĞÀÌÁÎÒÛ\AnonymChat\main.py", line 60, in start
    count_users = KeyboardButton(f'Â áîòå óæå {int(db.count_user() * 1.5)} ïîëüçîâàòåëåé\U0001f973')
                                                   ^^^^^^^^^^^^^^^
  File "D:\ÒÅËÅÃĞÀÌÁÎÒÛ\AnonymChat\database.py", line 82, in count_user
    result = self.cursor.execute('SELECT COUNT(*) FROM `users`').fetchone()
             ^^^^^^^^^^^^^^^^^^^^^^^^^^^^^^^^^^^^^^^^^^^^^^^^^^^
sqlite3.OperationalError: no such table: users
2023-01-29 02:11:19,183 - WARNING -no such table: users
2023-01-29 02:11:22,718 - WARNING -no such table: users
2023-01-29 02:11:22,793 - ERROR -Task exception was never retrieved
future: <Task finished name='Task-27' coro=<Dispatcher._process_polling_updates() done, defined at D:\Python\Lib\site-packages\aiogram\dispatcher\dispatcher.py:407> exception=ChatNotFound('Chat not found')>
Traceback (most recent call last):
  File "D:\ÒÅËÅÃĞÀÌÁÎÒÛ\AnonymChat\main.py", line 250, in chating
    await bot.send_message(db.select_connect_with(message.from_user.id)[0],user_data['msg']) #îòïğàâëÿåì ñîîáùåíèÿ ïîëüçîâàòåëÿ
                           ^^^^^^^^^^^^^^^^^^^^^^^^^^^^^^^^^^^^^^^^^^^^
  File "D:\ÒÅËÅÃĞÀÌÁÎÒÛ\AnonymChat\database.py", line 61, in select_connect_with
    return self.cursor.execute('SELECT `connect_with` FROM `users` WHERE `telegram_id` = ?',(telegram_id,)).fetchone()
           ^^^^^^^^^^^^^^^^^^^^^^^^^^^^^^^^^^^^^^^^^^^^^^^^^^^^^^^^^^^^^^^^^^^^^^^^^^^^^^^^^^^^^^^^^^^^^^^^
sqlite3.OperationalError: no such table: users

During handling of the above exception, another exception occurred:

Traceback (most recent call last):
  File "D:\Python\Lib\site-packages\aiogram\dispatcher\dispatcher.py", line 415, in _process_polling_updates
    for responses in itertools.chain.from_iterable(await self.process_updates(updates, fast)):
                                                   ^^^^^^^^^^^^^^^^^^^^^^^^^^^^^^^^^^^^^^^^^
  File "D:\Python\Lib\site-packages\aiogram\dispatcher\dispatcher.py", line 235, in process_updates
    return await asyncio.gather(*tasks)
           ^^^^^^^^^^^^^^^^^^^^^^^^^^^^
  File "D:\Python\Lib\site-packages\aiogram\dispatcher\handler.py", line 117, in notify
    response = await handler_obj.handler(*args, **partial_data)
               ^^^^^^^^^^^^^^^^^^^^^^^^^^^^^^^^^^^^^^^^^^^^^^^^
  File "D:\Python\Lib\site-packages\aiogram\dispatcher\dispatcher.py", line 256, in process_update
    return await self.message_handlers.notify(update.message)
           ^^^^^^^^^^^^^^^^^^^^^^^^^^^^^^^^^^^^^^^^^^^^^^^^^^
  File "D:\Python\Lib\site-packages\aiogram\dispatcher\handler.py", line 117, in notify
    response = await handler_obj.handler(*args, **partial_data)
               ^^^^^^^^^^^^^^^^^^^^^^^^^^^^^^^^^^^^^^^^^^^^^^^^
  File "D:\ÒÅËÅÃĞÀÌÁÎÒÛ\AnonymChat\main.py", line 264, in chating
    await send_to_channel_log_exception(message,e)
  File "D:\ÒÅËÅÃĞÀÌÁÎÒÛ\AnonymChat\main.py", line 302, in send_to_channel_log_exception
    await bot.send_message(-1001422742707,f'Îøèáêà\n\n{except_name}')
  File "D:\Python\Lib\site-packages\aiogram\bot\bot.py", line 346, in send_message
    result = await self.request(api.Methods.SEND_MESSAGE, payload)
             ^^^^^^^^^^^^^^^^^^^^^^^^^^^^^^^^^^^^^^^^^^^^^^^^^^^^^
  File "D:\Python\Lib\site-packages\aiogram\bot\base.py", line 236, in request
    return await api.make_request(await self.get_session(), self.server, self.__token, method, data, files,
           ^^^^^^^^^^^^^^^^^^^^^^^^^^^^^^^^^^^^^^^^^^^^^^^^^^^^^^^^^^^^^^^^^^^^^^^^^^^^^^^^^^^^^^^^^^^^^^^^
  File "D:\Python\Lib\site-packages\aiogram\bot\api.py", line 140, in make_request
    return check_result(method, response.content_type, response.status, await response.text())
           ^^^^^^^^^^^^^^^^^^^^^^^^^^^^^^^^^^^^^^^^^^^^^^^^^^^^^^^^^^^^^^^^^^^^^^^^^^^^^^^^^^^
  File "D:\Python\Lib\site-packages\aiogram\bot\api.py", line 115, in check_result
    exceptions.BadRequest.detect(description)
  File "D:\Python\Lib\site-packages\aiogram\utils\exceptions.py", line 140, in detect
    raise err(cls.text or description)
aiogram.utils.exceptions.ChatNotFound: Chat not found
2023-01-29 02:11:23,449 - WARNING -no such table: users
2023-01-29 02:12:04,466 - INFO -Bot: Àíîíèìíûé ×àò [@anonimchatarcher_bot]
2023-01-29 02:12:04,611 - WARNING -Updates were skipped successfully.
2023-01-29 02:12:04,612 - INFO -Start polling.
2023-01-29 02:12:13,932 - WARNING -no such table: users
2023-01-29 02:12:17,182 - ERROR -Task exception was never retrieved
future: <Task finished name='Task-12' coro=<Dispatcher._process_polling_updates() done, defined at D:\Python\Lib\site-packages\aiogram\dispatcher\dispatcher.py:407> exception=OperationalError('no such table: users')>
Traceback (most recent call last):
  File "D:\Python\Lib\site-packages\aiogram\dispatcher\dispatcher.py", line 415, in _process_polling_updates
    for responses in itertools.chain.from_iterable(await self.process_updates(updates, fast)):
                                                   ^^^^^^^^^^^^^^^^^^^^^^^^^^^^^^^^^^^^^^^^^
  File "D:\Python\Lib\site-packages\aiogram\dispatcher\dispatcher.py", line 235, in process_updates
    return await asyncio.gather(*tasks)
           ^^^^^^^^^^^^^^^^^^^^^^^^^^^^
  File "D:\Python\Lib\site-packages\aiogram\dispatcher\handler.py", line 117, in notify
    response = await handler_obj.handler(*args, **partial_data)
               ^^^^^^^^^^^^^^^^^^^^^^^^^^^^^^^^^^^^^^^^^^^^^^^^
  File "D:\Python\Lib\site-packages\aiogram\dispatcher\dispatcher.py", line 256, in process_update
    return await self.message_handlers.notify(update.message)
           ^^^^^^^^^^^^^^^^^^^^^^^^^^^^^^^^^^^^^^^^^^^^^^^^^^
  File "D:\Python\Lib\site-packages\aiogram\dispatcher\handler.py", line 117, in notify
    response = await handler_obj.handler(*args, **partial_data)
               ^^^^^^^^^^^^^^^^^^^^^^^^^^^^^^^^^^^^^^^^^^^^^^^^
  File "D:\ÒÅËÅÃĞÀÌÁÎÒÛ\AnonymChat\main.py", line 60, in start
    count_users = KeyboardButton(f'Â áîòå óæå {int(db.count_user() * 1.5)} ïîëüçîâàòåëåé\U0001f973')
                                                   ^^^^^^^^^^^^^^^
  File "D:\ÒÅËÅÃĞÀÌÁÎÒÛ\AnonymChat\database.py", line 82, in count_user
    result = self.cursor.execute('SELECT COUNT(*) FROM `users`').fetchone()
             ^^^^^^^^^^^^^^^^^^^^^^^^^^^^^^^^^^^^^^^^^^^^^^^^^^^
sqlite3.OperationalError: no such table: users
2023-01-29 02:12:31,121 - ERROR -Task exception was never retrieved
future: <Task finished name='Task-15' coro=<Dispatcher._process_polling_updates() done, defined at D:\Python\Lib\site-packages\aiogram\dispatcher\dispatcher.py:407> exception=OperationalError('no such table: users')>
Traceback (most recent call last):
  File "D:\Python\Lib\site-packages\aiogram\dispatcher\dispatcher.py", line 415, in _process_polling_updates
    for responses in itertools.chain.from_iterable(await self.process_updates(updates, fast)):
                                                   ^^^^^^^^^^^^^^^^^^^^^^^^^^^^^^^^^^^^^^^^^
  File "D:\Python\Lib\site-packages\aiogram\dispatcher\dispatcher.py", line 235, in process_updates
    return await asyncio.gather(*tasks)
           ^^^^^^^^^^^^^^^^^^^^^^^^^^^^
  File "D:\Python\Lib\site-packages\aiogram\dispatcher\handler.py", line 117, in notify
    response = await handler_obj.handler(*args, **partial_data)
               ^^^^^^^^^^^^^^^^^^^^^^^^^^^^^^^^^^^^^^^^^^^^^^^^
  File "D:\Python\Lib\site-packages\aiogram\dispatcher\dispatcher.py", line 256, in process_update
    return await self.message_handlers.notify(update.message)
           ^^^^^^^^^^^^^^^^^^^^^^^^^^^^^^^^^^^^^^^^^^^^^^^^^^
  File "D:\Python\Lib\site-packages\aiogram\dispatcher\handler.py", line 117, in notify
    response = await handler_obj.handler(*args, **partial_data)
               ^^^^^^^^^^^^^^^^^^^^^^^^^^^^^^^^^^^^^^^^^^^^^^^^
  File "D:\ÒÅËÅÃĞÀÌÁÎÒÛ\AnonymChat\main.py", line 60, in start
    count_users = KeyboardButton(f'Â áîòå óæå {int(db.count_user() * 1.5)} ïîëüçîâàòåëåé\U0001f973')
                                                   ^^^^^^^^^^^^^^^
  File "D:\ÒÅËÅÃĞÀÌÁÎÒÛ\AnonymChat\database.py", line 82, in count_user
    result = self.cursor.execute('SELECT COUNT(*) FROM `users`').fetchone()
             ^^^^^^^^^^^^^^^^^^^^^^^^^^^^^^^^^^^^^^^^^^^^^^^^^^^
sqlite3.OperationalError: no such table: users
